<mujoco model="Taks_T1">
    <compiler angle="radian" balanceinertia="true"/>

    <option iterations="3" ls_iterations="5" timestep=".002" integrator="Euler">
        <flag eulerdamp="disable"/>
    </option>

    <default>
        <default class="Taks_T1">
            <geom condim="1" contype="0" conaffinity="0"/>
            <joint damping="0.05" armature="0.01" frictionloss="0.2"/>

            <default class="hip">
                <default class="hip_pitch">
                    <joint axis="0 1 0" range="-2.5307 2.8798" actuatorfrcrange="-120 120" armature="0.01017752004"/>
                </default>
                <default class="hip_roll">
                    <joint axis="1 0 0" actuatorfrcrange="-97 97" armature="0.025101925"/>
                </default>
                <default class="hip_yaw">
                    <joint axis="0 0 1" range="-2.7576 2.7576" actuatorfrcrange="-97 97" armature="0.01017752004"/>
                </default>
            </default>
            <default class="knee">
                <joint axis="0 1 0" range="-0.087267 2.8798" actuatorfrcrange="-120 120" armature="0.025101925"/>
            </default>
            <default class="ankle">
                <default class="ankle_pitch">
                    <joint axis="0 1 0" range="-0.87267 0.5236" actuatorfrcrange="-27 27" armature="0.00721945"/>
                </default>
                <default class="ankle_roll">
                    <joint axis="1 0 0" range="-0.2618 0.2618" actuatorfrcrange="-27 27" armature="0.00721945"/>
                </default>
            </default>
            <default class="waist_yaw">
                <joint axis="0 0 1" range="-2.618 2.618" actuatorfrcrange="-97 97" armature="0.01017752004"/>
            </default>
            <default class="waist_pitch">
                <joint axis="0 1 0" range="-0.52 0.52" actuatorfrcrange="-97 97" armature="0.00721945"/>
            </default>
            <default class="waist_roll">
                <joint axis="1 0 0" range="-0.52 0.52" actuatorfrcrange="-97 97" armature="0.00721945"/>
            </default>
            <default class="shoulder">
                <default class="shoulder_pitch">
                    <joint axis="0 1 0" range="-3.0 2.0" actuatorfrcrange="-27 27" armature="0.003609725"/>
                </default>
                <default class="shoulder_roll">
                    <joint axis="1 0 0" actuatorfrcrange="-27 27" armature="0.003609725"/>
                </default>
                <default class="shoulder_yaw">
                    <joint axis="0 0 1" range="-2.58 2.58" actuatorfrcrange="-27 27" armature="0.003609725"/>
                </default>
            </default>
            <default class="elbow">
                <joint axis="0 1 0" range="-0.7 1.57" actuatorfrcrange="-27 27" armature="0.003609725"/>
            </default>
            <default class="wrist">
                <default class="wrist_roll">
                    <joint axis="1 0 0" range="-2.67 2.67" actuatorfrcrange="-7 7" armature="0.003609725"/>
                </default>
                <default class="wrist_pitch">
                    <joint axis="0 1 0" range="-0.9 0.9" actuatorfrcrange="-7 7" armature="0.00425"/>
                </default>
                <default class="wrist_yaw">
                    <joint axis="0 0 1" range="-0.9 0.9" actuatorfrcrange="-7 7" armature="0.00425"/>
                </default>
            </default>
            <default class="neck">
                <default class="neck_yaw">
                    <joint axis="0 0 1" range="-1.57 1.57" actuatorfrcrange="-3 3" armature="0.001"/>
                </default>
                <default class="neck_roll">
                    <joint axis="1 0 0" range="-0.873 0.873" actuatorfrcrange="-3 3" armature="0.001"/>
                </default>
                <default class="neck_pitch">
                    <joint axis="0 1 0" range="-0.873 0.873" actuatorfrcrange="-3 3" armature="0.001"/>
                </default>
            </default>

            <default class="visual">
                <geom group="2" type="mesh" density="0" material="silver"/>
            </default>
            <default class="collision">
                <geom group="3" rgba=".2 .6 .2 .3"/>
                <default class="foot">
                    <geom size="0.085 0.03 0.005"/>
                </default>
            </default>
            <site group="5" rgba="1 0 0 1"/>
        </default>
    </default>

    <asset>
        <material name="silver" rgba="1 1 1 1"/>
        <material name="white" rgba="1 1 1 1"/>

        <mesh name="pelvis" file="meshes/pelvis.STL"/>
        <mesh name="left_hip_pitch_link" file="meshes/left_hip_pitch_link.STL"/>
        <mesh name="left_hip_roll_link" file="meshes/left_hip_roll_link.STL"/>
        <mesh name="left_hip_yaw_link" file="meshes/left_hip_yaw_link.STL"/>
        <mesh name="left_knee_link" file="meshes/left_knee_link.STL"/>
        <mesh name="left_ankle_pitch_link" file="meshes/left_ankle_pitch_link.STL"/>
        <mesh name="left_ankle_roll_link" file="meshes/left_ankle_roll_link.STL"/>
        <mesh name="right_hip_pitch_link" file="meshes/right_hip_pitch_link.STL"/>
        <mesh name="right_hip_roll_link" file="meshes/right_hip_roll_link.STL"/>
        <mesh name="right_hip_yaw_link" file="meshes/right_hip_yaw_link.STL"/>
        <mesh name="right_knee_link" file="meshes/right_knee_link.STL"/>
        <mesh name="right_ankle_pitch_link" file="meshes/right_ankle_pitch_link.STL"/>
        <mesh name="right_ankle_roll_link" file="meshes/right_ankle_roll_link.STL"/>
        <mesh name="waist_yaw_link" file="meshes/waist_yaw_link.STL"/>
        <mesh name="waist_roll_link" file="meshes/waist_roll_link.STL"/>
        <mesh name="torso_link" file="meshes/waist_pitch_link.STL"/>
        <mesh name="left_shoulder_pitch_link" file="meshes/left_shoulder_pitch_link.STL"/>
        <mesh name="left_shoulder_roll_link" file="meshes/left_shoulder_roll_link.STL"/>
        <mesh name="left_shoulder_yaw_link" file="meshes/left_shoulder_yaw_link.STL"/>
        <mesh name="left_elbow_link" file="meshes/left_elbow_link.STL"/>
        <mesh name="left_wrist_roll_link" file="meshes/left_wrist_roll_link.STL"/>
        <mesh name="left_wrist_yaw_link" file="meshes/left_wrist_yaw_link.STL"/>
        <mesh name="left_wrist_pitch_link" file="meshes/left_wrist_pitch_link.STL"/>
        <mesh name="right_shoulder_pitch_link" file="meshes/right_shoulder_pitch_link.STL"/>
        <mesh name="right_shoulder_roll_link" file="meshes/right_shoulder_roll_link.STL"/>
        <mesh name="right_shoulder_yaw_link" file="meshes/right_shoulder_yaw_link.STL"/>
        <mesh name="right_elbow_link" file="meshes/right_elbow_link.STL"/>
        <mesh name="right_wrist_roll_link" file="meshes/right_wrist_roll_link.STL"/>
        <mesh name="right_wrist_yaw_link" file="meshes/right_wrist_yaw_link.STL"/>
        <mesh name="right_wrist_pitch_link" file="meshes/right_wrist_pitch_link.STL"/>
        <mesh name="neck_yaw_link" file="meshes/neck_yaw_link.STL"/>
        <mesh name="neck_roll_link" file="meshes/neck_roll_link.STL"/>
        <mesh name="neck_pitch_link" file="meshes/neck_pitch_link.STL"/>
    </asset>

    <worldbody>
        <body name="pelvis" pos="0 0 0.793" childclass="Taks_T1">
            <inertial pos="0 0 -0.05192" mass="3.2" diaginertia="0.0161067 0.0106667 0.0200852"/>
            <freejoint name="root"/>
            <geom class="visual" material="white" mesh="pelvis"/>
            <geom name="pelvis_collision" class="collision" type="sphere" size="0.08" pos="0 0 -0.05" contype="1" conaffinity="0"/>
            <site name="imu_in_pelvis" size="0.01" pos="0 0 0"/>

            <!-- Left Leg -->
            <body name="left_hip_pitch_link" pos="0 0.115 -0.0523">
                <inertial pos="-0.02022 0.04885 -0.00359" mass="0.685" diaginertia="0.000776333 0.000570833 0.000936167"/>
                <joint name="left_hip_pitch_joint" class="hip_pitch"/>
                <geom class="visual" mesh="left_hip_pitch_link"/>
                <body name="left_hip_roll_link" pos="0.007945 0.053348 0.001351" quat="0.996195 0 -0.087156 0">
                    <inertial pos="-0.00668 -0.00027 -0.0695" mass="0.93" diaginertia="0.001612 0.001612 0.000992"/>
                    <joint name="left_hip_roll_joint" range="-0.5236 2.9671" class="hip_roll"/>
                    <geom class="visual" mesh="left_hip_roll_link"/>
                    <geom name="left_thigh" class="collision" type="capsule" size="0.06" fromto="0.02 0 0 0.02 0 -0.20"/>
                    <body name="left_hip_yaw_link" pos="-0.008293 0 -0.10937">
                        <inertial pos="-0.048416 -0.008192 -0.200621" mass="1.74" diaginertia="0.014616 0.014616 0.003132"/>
                        <joint name="left_hip_yaw_joint" class="hip_yaw"/>
                        <geom class="visual" mesh="left_hip_yaw_link"/>
                        <body name="left_knee_link" pos="-0.060138 0.016849 -0.23297" quat="0.996195 0 0.087156 0">
                            <inertial pos="0 -0.02480 -0.115572" mass="0.63" diaginertia="0.004977 0.004977 0.000504"/>
                            <joint name="left_knee_joint" class="knee"/>
                            <geom class="visual" mesh="left_knee_link"/>
                            <geom name="left_shin" class="collision" type="capsule" size="0.06" fromto="0.02 0 0 0.02 0 -0.25"/>
                            <body name="left_ankle_pitch_link" pos="0 -0.015197 -0.28503">
                                <inertial pos="0.019984 0 0" mass="0.001837" diaginertia="1.6533e-07 1.6533e-07 1.6533e-07"/>
                                <joint name="left_ankle_pitch_joint" class="ankle_pitch"/>
                                <geom class="visual" mesh="left_ankle_pitch_link"/>
                                <body name="left_ankle_roll_link" pos="0.02 0 0">
                                    <site name="left_foot" rgba="1 0 0 1"/>
                                    <site name="left_foot_top" pos="0.12 0 -0.045"/>
                                    <inertial pos="0.025052 -0.005381 -0.04" mass="0.56" diaginertia="0.000415333 0.00146533 0.00164733"/>
                                    <joint name="left_ankle_roll_joint" class="ankle_roll"/>
                                    <geom class="visual" material="white" mesh="left_ankle_roll_link"/>
                                    <geom name="left_foot" class="foot" pos="0.035 0 -0.045" size="0.085 0.03 0.008" type="box"/>
                                </body>
                            </body>
                        </body>
                    </body>
                </body>
            </body>

            <!-- Right Leg -->
            <body name="right_hip_pitch_link" pos="0 -0.115 -0.0523">
                <inertial pos="-0.02022 -0.04886 -0.00359" mass="0.685" diaginertia="0.000776333 0.000570833 0.000936167"/>
                <joint name="right_hip_pitch_joint" class="hip_pitch"/>
                <geom class="visual" mesh="right_hip_pitch_link"/>
                <body name="right_hip_roll_link" pos="0.007945 -0.053348 0.001351" quat="0.996195 0 -0.087156 0">
                    <inertial pos="-0.00668 0.00027 -0.0695" mass="0.93" diaginertia="0.001612 0.001612 0.000992"/>
                    <joint name="right_hip_roll_joint" range="-2.9671 0.5236" class="hip_roll"/>
                    <geom class="visual" mesh="right_hip_roll_link"/>
                    <geom name="right_thigh" class="collision" type="capsule" size="0.06" fromto="0.02 0 0 0.02 0 -0.20"/>
                    <body name="right_hip_yaw_link" pos="-0.008293 0 -0.10937">
                        <inertial pos="-0.04842 0.008194 -0.200625" mass="1.74" diaginertia="0.014616 0.014616 0.003132"/>
                        <joint name="right_hip_yaw_joint" class="hip_yaw"/>
                        <geom class="visual" mesh="right_hip_yaw_link"/>
                        <body name="right_knee_link" pos="-0.060138 -0.016849 -0.23297" quat="0.996195 0 0.087156 0">
                            <inertial pos="0 0.02480 -0.115573" mass="0.63" diaginertia="0.004977 0.004977 0.000504"/>
                            <joint name="right_knee_joint" class="knee"/>
                            <geom class="visual" mesh="right_knee_link"/>
                            <geom name="right_shin" class="collision" type="capsule" size="0.06" fromto="0.02 0 0 0.02 0 -0.25"/>
                            <body name="right_ankle_pitch_link" pos="0 0.015197 -0.28503">
                                <inertial pos="0.019984 0 0" mass="0.001837" diaginertia="1.6533e-07 1.6533e-07 1.6533e-07"/>
                                <joint name="right_ankle_pitch_joint" class="ankle_pitch"/>
                                <geom class="visual" mesh="right_ankle_pitch_link"/>
                                <body name="right_ankle_roll_link" pos="0.02 0 0">
                                    <site name="right_foot" pos="0 0 0"/>
                                    <site name="right_foot_top" pos="0.12 0 -0.045"/>
                                    <inertial pos="0.025052 0.005381 -0.04" mass="0.56" diaginertia="0.000415333 0.00146533 0.00164733"/>
                                    <joint name="right_ankle_roll_joint" class="ankle_roll"/>
                                    <geom class="visual" material="white" mesh="right_ankle_roll_link"/>
                                    <geom name="right_foot" class="foot" pos="0.035 0 -0.045" size="0.085 0.03 0.008" type="box"/>
                                </body>
                            </body>
                        </body>
                    </body>
                </body>
            </body>

            <!-- Upper Body -->
            <body name="waist_yaw_link">
                <inertial pos="0.000694 0.000037 0.023535" mass="0.79" diaginertia="0.00073075 0.00073075 0.0009875"/>
                <joint name="waist_yaw_joint" class="waist_yaw"/>
                <geom class="visual" mesh="waist_yaw_link"/>
                <body name="waist_roll_link" pos="0.03813 0.000037 0.050906">
                    <inertial pos="-0.03647 0.001918 0.039525" mass="1.56" diaginertia="0.0056 0.0056 0.0026"/>
                    <joint name="waist_roll_joint" class="waist_roll"/>
                    <geom class="visual" mesh="waist_roll_link"/>
                    <body name="torso_link" pos="-0.03813 -0.032925 0.079963">
                        <inertial pos="-0.000232 0.028443 0.216034" mass="2.01" diaginertia="0.025875 0.0192688 0.0148437"/>
                        <joint name="waist_pitch_joint" class="waist_pitch"/>
                        <geom class="visual" mesh="torso_link"/>
                        <geom name="torso" class="collision" type="capsule" size="0.09" fromto="0 0 0.06 0 0 0.35"/>
                        <site name="imu_in_torso" size="0.01" pos="0 0.028 0.216"/>
                        
                        <!-- Left Arm -->
                        <body name="left_shoulder_pitch_link" pos="0 0.13582 0.33654" quat="0.965926 0.258819 0 0">
                            <inertial pos="-0.003513 0.038593 0.000147" mass="0.24" diaginertia="0.000178 0.000122 0.0002"/>
                            <joint name="left_shoulder_pitch_joint" class="shoulder_pitch"/>
                            <geom class="visual" mesh="left_shoulder_pitch_link"/>
                            <body name="left_shoulder_roll_link" pos="0.03476 0.0835 0.000425" quat="0.965926 -0.258819 0 0">
                                <inertial pos="-0.034364 0.004091 -0.054537" mass="0.92" diaginertia="0.00157167 0.00178633 0.000766667"/>
                                <joint name="left_shoulder_roll_joint" range="-0.2 2.2515" class="shoulder_roll"/>
                                <geom class="visual" mesh="left_shoulder_roll_link"/>
                                <body name="left_shoulder_yaw_link" pos="-0.034375 0 -0.12">
                                    <inertial pos="0.000365 -0.000072 -0.086229" mass="0.625" diaginertia="0.0019375 0.0019375 0.0005"/>
                                    <joint name="left_shoulder_yaw_joint" class="shoulder_yaw"/>
                                    <geom class="visual" mesh="left_shoulder_yaw_link"/>
                                    <geom name="left_shoulder_yaw_collision" class="collision" type="capsule" size="0.035" fromto="0 0 -0.03 0 0 0.11"/>
                                    <body name="left_elbow_link" pos="0.000364 0.029113 -0.18099">
                                        <inertial pos="0.060258 -0.018902 -0.00551" mass="0.552" diaginertia="0.0003381 0.00094645 0.00094645"/>
                                        <joint name="left_elbow_joint" class="elbow"/>
                                        <geom class="visual" mesh="left_elbow_link"/>
                                        <geom name="left_elbow_yaw_collision" class="collision" type="capsule" size="0.035" fromto="-0.01 0 -0.01 0.08 0 -0.01"/>
                                        <body name="left_wrist_roll_link" pos="0.13 -0.029125 0">
                                            <inertial pos="0.059349 0 0.000843" mass="0.508" diaginertia="0.0002286 0.0007239 0.0007239"/>
                                            <joint name="left_wrist_roll_joint" class="wrist_roll"/>
                                            <geom class="visual" mesh="left_wrist_roll_link"/>
                                            <body name="left_wrist_yaw_link" pos="0.121 0 -0.0333">
                                                <inertial pos="0 0.001805 0.034219" mass="0.37" diaginertia="0.000228167 0.000228167 0.000154167"/>
                                                <joint name="left_wrist_yaw_joint" class="wrist_yaw"/>
                                                <geom class="visual" mesh="left_wrist_yaw_link"/>
                                                <body name="left_wrist_pitch_link" pos="0 0.022502 0.033299">
                                                    <inertial pos="0.076857 -0.017165 0.011311" mass="0.28" diaginertia="0.000121333 0.000270667 0.000317333"/>
                                                    <joint name="left_wrist_pitch_joint" class="wrist_pitch"/>
                                                    <geom class="visual" mesh="left_wrist_pitch_link"/>
                                                    <geom name="left_wrist_pitch_collision" class="collision" type="capsule" size="0.04" fromto="0.05 0 0 0.1 0 0"/>
                                                    <site name="left_palm" pos="0.08 0 0" size="0.01"/>
                                                    <geom name="left_hand_collision" class="collision" type="capsule" size="0.05" fromto="0.08 0 0 0.13 0 0" rgba=".2 .6 .2 .2"/>
                                                </body>
                                            </body>
                                        </body>
                                    </body>
                                </body>
                            </body>
                        </body>

                        <!-- Right Arm -->
                        <body name="right_shoulder_pitch_link" pos="0 -0.069974 0.33654" quat="0.965926 -0.258819 0 0">
                            <inertial pos="-0.003513 -0.038593 0.000147" mass="0.24" diaginertia="0.000178 0.000122 0.0002"/>
                            <joint name="right_shoulder_pitch_joint" range="-2.0 2.0" class="shoulder_pitch"/>
                            <geom class="visual" mesh="right_shoulder_pitch_link"/>
                            <body name="right_shoulder_roll_link" pos="0.02776 -0.0835 0.000425" quat="0.965926 0.258819 0 0">
                                <inertial pos="-0.027363 -0.004095 -0.054537" mass="0.92" diaginertia="0.00157167 0.00178633 0.000766667"/>
                                <joint name="right_shoulder_roll_joint" range="-2.2515 0.2" class="shoulder_roll"/>
                                <geom class="visual" mesh="right_shoulder_roll_link"/>
                                <body name="right_shoulder_yaw_link" pos="-0.027375 0 -0.12">
                                    <inertial pos="0.000364 0.000066 -0.08623" mass="0.625" diaginertia="0.0019375 0.0019375 0.0005"/>
                                    <joint name="right_shoulder_yaw_joint" class="shoulder_yaw"/>
                                    <geom class="visual" mesh="right_shoulder_yaw_link"/>
                                    <geom name="right_shoulder_yaw_collision" class="collision" type="capsule" size="0.035" fromto="0 0 -0.03 0 0 0.11"/>
                                    <body name="right_elbow_link" pos="0.000364 0.027375 -0.18099">
                                        <inertial pos="0.060603 -0.027325 -0.005367" mass="0.552" diaginertia="0.0003381 0.00094645 0.0003381"/>
                                        <joint name="right_elbow_joint" class="elbow"/>
                                        <geom class="visual" mesh="right_elbow_link"/>
                                        <geom name="right_elbow_yaw_collision" class="collision" type="capsule" size="0.035" fromto="-0.01 0 -0.01 0.08 0 -0.01"/>
                                        <body name="right_wrist_roll_link" pos="0.13 -0.027375 0">
                                            <inertial pos="0.059331 0 0.000847" mass="0.508" diaginertia="0.0002286 0.0007239 0.0007239"/>
                                            <joint name="right_wrist_roll_joint" class="wrist_roll"/>
                                            <geom class="visual" mesh="right_wrist_roll_link"/>
                                            <body name="right_wrist_yaw_link" pos="0.121 0 -0.0333">
                                                <inertial pos="0 -0.001803 0.034219" mass="0.37" diaginertia="0.000228167 0.000228167 0.000154167"/>
                                                <joint name="right_wrist_yaw_joint" class="wrist_yaw"/>
                                                <geom class="visual" mesh="right_wrist_yaw_link"/>
                                                <body name="right_wrist_pitch_link" pos="0 -0.0225 0.0333">
                                                    <inertial pos="0.076858 0.017168 0.01131" mass="0.28" diaginertia="0.000121333 0.000270667 0.000317333"/>
                                                    <joint name="right_wrist_pitch_joint" class="wrist_pitch"/>
                                                    <geom class="visual" mesh="right_wrist_pitch_link"/>
                                                    <geom name="right_wrist_pitch_collision" class="collision" type="capsule" size="0.04" fromto="0.05 0 0 0.1 0 0"/>
                                                    <site name="right_palm" pos="0.08 0 0" size="0.01"/>
                                                    <geom name="right_hand_collision" class="collision" type="capsule" size="0.05" fromto="0.08 0 0 0.13 0 0" rgba=".2 .6 .2 .2"/>
                                                </body>
                                            </body>
                                        </body>
                                    </body>
                                </body>
                            </body>
                        </body>

                        <!-- Neck -->
                        <body name="neck_yaw_link" pos="0 0.032906 0.37165">
                            <inertial pos="-0.026005 0 0.044508" mass="0.4" diaginertia="0.000483333 0.000483333 0.000426667"/>
                            <joint name="neck_yaw_joint" class="neck_yaw"/>
                            <geom class="visual" mesh="neck_yaw_link"/>
                            <body name="neck_roll_link" pos="-0.0719 0 0.0708">
                                <inertial pos="0.05706 -0.000635 0" mass="0.026" diaginertia="1.04e-05 1.04e-05 5.2e-06"/>
                                <joint name="neck_roll_joint" class="neck_roll"/>
                                <geom class="visual" mesh="neck_roll_link"/>
                                <body name="neck_pitch_link" pos="0.0719 0.02095 0">
                                    <inertial pos="0.009314 -0.020599 0.085269" mass="0.6" diaginertia="0.001845 0.001845 0.00144"/>
                                    <joint name="neck_pitch_joint" class="neck_pitch"/>
                                    <geom class="visual" mesh="neck_pitch_link"/>
                                </body>
                            </body>
                        </body>
                    </body>
                </body>
            </body>
        </body>
    </worldbody>

    <contact>
        <pair name="left_hand_thigh" geom1="left_hand_collision" geom2="left_thigh" condim="1"/>
        <pair name="right_hand_thigh" geom1="right_hand_collision" geom2="right_thigh" condim="1"/>
        <pair name="left_foot_right_foot" geom1="left_foot" geom2="right_foot" condim="1"/>
        <pair name="left_foot_right_shin" geom1="left_foot" geom2="right_shin" condim="1"/>
        <pair name="right_foot_left_shin" geom1="right_foot" geom2="left_shin" condim="1"/>
        <pair name="left_shin_right_shin" geom1="left_shin" geom2="right_shin" condim="1"/>
        <pair name="left_hand_right_hand" geom1="left_hand_collision" geom2="right_hand_collision" condim="1"/>
        <pair name="left_hand_right_wrist_pitch" geom1="left_hand_collision" geom2="right_wrist_pitch_collision" condim="1"/>
        <pair name="right_hand_left_wrist_pitch" geom1="right_hand_collision" geom2="left_wrist_pitch_collision" condim="1"/>
        <pair name="right_hand_torso" geom1="right_hand_collision" geom2="torso" condim="1"/>
        <pair name="left_hand_torso" geom1="left_hand_collision" geom2="torso" condim="1"/>
        <pair name="right_shoulder_torso" geom1="right_shoulder_yaw_collision" geom2="torso" condim="1"/>
        <pair name="left_shoulder_torso" geom1="left_shoulder_yaw_collision" geom2="torso" condim="1"/>
        <pair name="right_elbow_torso" geom1="right_elbow_yaw_collision" geom2="torso" condim="1"/>
        <pair name="left_elbow_torso" geom1="left_elbow_yaw_collision" geom2="torso" condim="1"/>
    </contact>

    <actuator>
        <position name="left_hip_pitch_joint" joint="left_hip_pitch_joint" kp="100" kv="2" forcerange="-120 120" forcelimited="true"/>
        <position name="left_hip_roll_joint" joint="left_hip_roll_joint" kp="100" kv="2" forcerange="-97 97" forcelimited="true"/>
        <position name="left_hip_yaw_joint" joint="left_hip_yaw_joint" kp="100" kv="2" forcerange="-97 97" forcelimited="true"/>
        <position name="left_knee_joint" joint="left_knee_joint" kp="200" kv="4" forcerange="-120 120" forcelimited="true"/>
        <position name="left_ankle_pitch_joint" joint="left_ankle_pitch_joint" kp="80" kv="2" forcerange="-27 27" forcelimited="true"/>
        <position name="left_ankle_roll_joint" joint="left_ankle_roll_joint" kp="20" kv="1" forcerange="-27 27" forcelimited="true"/>

        <position name="right_hip_pitch_joint" joint="right_hip_pitch_joint" kp="100" kv="2" forcerange="-120 120" forcelimited="true"/>
        <position name="right_hip_roll_joint" joint="right_hip_roll_joint" kp="100" kv="2" forcerange="-97 97" forcelimited="true"/>
        <position name="right_hip_yaw_joint" joint="right_hip_yaw_joint" kp="100" kv="2" forcerange="-97 97" forcelimited="true"/>
        <position name="right_knee_joint" joint="right_knee_joint" kp="200" kv="4" forcerange="-120 120" forcelimited="true"/>
        <position name="right_ankle_pitch_joint" joint="right_ankle_pitch_joint" kp="80" kv="2" forcerange="-27 27" forcelimited="true"/>
        <position name="right_ankle_roll_joint" joint="right_ankle_roll_joint" kp="20" kv="1" forcerange="-27 27" forcelimited="true"/>

        <position name="waist_yaw_joint" joint="waist_yaw_joint" kp="300" kv="10" forcerange="-97 97" forcelimited="true"/>
        <position name="waist_roll_joint" joint="waist_roll_joint" kp="300" kv="10" forcerange="-97 97" forcelimited="true"/>
        <position name="waist_pitch_joint" joint="waist_pitch_joint" kp="300" kv="10" forcerange="-97 97" forcelimited="true"/>

        <position name="left_shoulder_pitch_joint" joint="left_shoulder_pitch_joint" kp="90" kv="2" forcerange="-27 27" forcelimited="true"/>
        <position name="left_shoulder_roll_joint" joint="left_shoulder_roll_joint" kp="60" kv="2" forcerange="-27 27" forcelimited="true"/>
        <position name="left_shoulder_yaw_joint" joint="left_shoulder_yaw_joint" kp="20" kv="1" forcerange="-27 27" forcelimited="true"/>
        <position name="left_elbow_joint" joint="left_elbow_joint" kp="60" kv="1" forcerange="-27 27" forcelimited="true"/>
        <position name="left_wrist_roll_joint" joint="left_wrist_roll_joint" kp="20" kv="1" forcerange="-7 7" forcelimited="true"/>
        <position name="left_wrist_yaw_joint" joint="left_wrist_yaw_joint" kp="20" kv="1" forcerange="-7 7" forcelimited="true"/>
        <position name="left_wrist_pitch_joint" joint="left_wrist_pitch_joint" kp="20" kv="1" forcerange="-7 7" forcelimited="true"/>

        <position name="right_shoulder_pitch_joint" joint="right_shoulder_pitch_joint" kp="90" kv="2" forcerange="-27 27" forcelimited="true"/>
        <position name="right_shoulder_roll_joint" joint="right_shoulder_roll_joint" kp="60" kv="2" forcerange="-27 27" forcelimited="true"/>
        <position name="right_shoulder_yaw_joint" joint="right_shoulder_yaw_joint" kp="20" kv="1" forcerange="-27 27" forcelimited="true"/>
        <position name="right_elbow_joint" joint="right_elbow_joint" kp="60" kv="1" forcerange="-27 27" forcelimited="true"/>
        <position name="right_wrist_roll_joint" joint="right_wrist_roll_joint" kp="20" kv="1" forcerange="-7 7" forcelimited="true"/>
        <position name="right_wrist_yaw_joint" joint="right_wrist_yaw_joint" kp="20" kv="1" forcerange="-7 7" forcelimited="true"/>
        <position name="right_wrist_pitch_joint" joint="right_wrist_pitch_joint" kp="20" kv="1" forcerange="-7 7" forcelimited="true"/>

        <position name="neck_yaw_joint" joint="neck_yaw_joint" kp="20" kv="1" forcerange="-3 3" forcelimited="true"/>
        <position name="neck_roll_joint" joint="neck_roll_joint" kp="20" kv="1" forcerange="-3 3" forcelimited="true"/>
        <position name="neck_pitch_joint" joint="neck_pitch_joint" kp="20" kv="1" forcerange="-3 3" forcelimited="true"/>
    </actuator>

    <sensor>
        <framezaxis objtype="site" objname="imu_in_torso" name="upvector_torso"/>
        <velocimeter site="imu_in_torso" name="local_linvel_torso"/>
        <velocimeter site="imu_in_pelvis" name="local_linvel_pelvis"/>
        <accelerometer site="imu_in_torso" name="accelerometer_torso"/>
        <accelerometer site="imu_in_pelvis" name="accelerometer_pelvis"/>
        <gyro site="imu_in_torso" name="gyro_torso"/>
        <gyro site="imu_in_pelvis" name="gyro_pelvis"/>
        <framezaxis objtype="site" objname="imu_in_pelvis" name="upvector_pelvis"/>
        <framexaxis objtype="site" objname="imu_in_torso" name="forwardvector_torso"/>
        <framexaxis objtype="site" objname="imu_in_pelvis" name="forwardvector_pelvis"/>
        <framequat objtype="site" objname="imu_in_torso" name="orientation_torso"/>
        <framequat objtype="site" objname="imu_in_pelvis" name="orientation_pelvis"/>
        <framelinvel objtype="site" objname="imu_in_torso" name="global_linvel_torso"/>
        <framelinvel objtype="site" objname="imu_in_pelvis" name="global_linvel_pelvis"/>
        <frameangvel objtype="site" objname="imu_in_torso" name="global_angvel_torso"/>
        <frameangvel objtype="site" objname="imu_in_pelvis" name="global_angvel_pelvis"/>
        <framelinvel objtype="site" objname="left_foot" name="left_foot_global_linvel"/>
        <framelinvel objtype="site" objname="right_foot" name="right_foot_global_linvel"/>
        <framezaxis objtype="site" objname="left_foot" name="left_foot_upvector"/>
        <framezaxis objtype="site" objname="right_foot" name="right_foot_upvector"/>
        <force name="left_foot_force" site="left_foot"/>
        <force name="right_foot_force" site="right_foot"/>
    </sensor>
</mujoco>